Workbook

Sheet 总结
A1: 总胜率 | B1: 总盈亏 | C1: 平均盈利金额 | D1: 平均亏损金额 | E1: 盈亏比
A2: =COUNTIF(日志重制!Q:Q,"盈利")/(COUNTIF(日志重制!Q:Q,"盈利")+COUNTIF(日志重制!Q:Q,"亏损")) -> 1 | B2: =SUM(日志重制!R:R) -> 10.55 | C2: =AVERAGEIF(日志重制!R:R,">0") -> 3.5166667 | D2: =AVERAGEIF(日志重制!T:T,"<0") -> #DIV/0! | E2: =C2/-D2 -> #DIV/0!

Sheet 日志重制
A1: 日期 | B1: 标的 | C1: 入场理由 | D1: 入场类型 | E1: 离场理由/方式 | F1: 分析说明 | G1: 仓位 | H1: 方向 | I1: 手续费 | J1: 开仓均价 | K1: 平仓均价 | L1: 止盈价 | M1: 止损价 | N1: 开仓净额 | O1: 平仓净额 | P1: 平仓净额2 | Q1: 盈亏状态 | R1: 盈亏金额 | S1: 累计盈亏 | T1: 错误原因 | U1: 复盘图像
A2: 46028.948 | B2: MES | C2: 跳空开盘延续 | D2: 趋势延续 | E2: 觉得有逆势压提前止盈 | F2: 大幅高开，预期强势上涨趋势延续，目标位跳空缺口向上1.705倍MM，K4-K6有交易转区间趋势，因此将目标位调整为前高之下提前离场，后续顺利到达原定目标位。 | G2: 1 | H2: 多 | I2: =0.62*2 -> 1.24 | J2: 6945.75 | K2: 6948 | L2: / | M2: / | N2: 34728.75 | O2: 34740 | Q2: =_xlfn.IFS(R2>0,"盈利",R2<0,"亏损",R2=0,"打平") -> 盈利 | R2: =IF(ISBLANK(P2),IF(H2="多",(O2-N2)*G2,(N2-O2)*G2)-I2,IF(H2="多",(O2-N2)*(G2/2)+(P2-N2)*(G2/2)-I2,(N2-O2)*(G2/2)+(N2-P2)*(G2/2))-I2) -> 10.01 | S2: =SUM($R$2:R2) -> 10.01 | T2: 盈利单但是提前离场 | U2: #VALUE!
A3: 46029.993 | B3: US500 | C3: 强趋势50%回调 | D3: 趋势延续 | E3: 回测通道起点 | F3: 大幅高开，预期强势上涨延续，上涨50%回调处挂限价单0.03手，目标位上涨急速顶点。 | G3: 1 | H3: 多 | I3: 0 | J3: 6923.4 | K3: 6937 | L3: 6937 | M3: 6907 | N3: 207.7 | O3: 208.11 | Q3: =_xlfn.IFS(R3>0,"盈利",R3<0,"亏损",R3=0,"打平") -> 盈利 | R3: =IF(ISBLANK(P3),IF(H3="多",(O3-N3)*G3,(N3-O3)*G3)-I3,IF(H3="多",(O3-N3)*(G3/2)+(P3-N3)*(G3/2)-I3,(N3-O3)*(G3/2)+(N3-P3)*(G3/2))-I3) -> 0.41 | S3: =SUM($R$2:R3) -> 10.42 | U3: #VALUE!
A4: 46029.896 | B4: US500 | C4: 三推楔形、双底 | D4: 反转 | E4: 回测通道起点 | F4: 宽通道下跌，双重底反向突破前期高点创新高，回调再次突破新高入场，目标位下跌通道起点。 | G4: 1 | H4: 多 | I4: 0 | J4: 6498.13 | K4: 6952.17 | L4: 6952.21 | M4: 6943.11 | N4: 208.44 | O4: 208.57 | Q4: =_xlfn.IFS(R4>0,"盈利",R4<0,"亏损",R4=0,"打平") -> 盈利 | R4: =IF(ISBLANK(P4),IF(H4="多",(O4-N4)*G4,(N4-O4)*G4)-I4,IF(H4="多",(O4-N4)*(G4/2)+(P4-N4)*(G4/2)-I4,(N4-O4)*(G4/2)+(N4-P4)*(G4/2))-I4) -> 0.13 | S4: =SUM($R$2:R4) -> 10.55 | U4: #VALUE!

Sheet 入场理由
A1: 入场理由 | B1: 盈亏金额 | C1: 胜率 | D1: 使用次数
A2: 不知道为什么开仓 | B2: =SUMIF(日志重制!C:C,A2,日志重制!R:R) -> 0 | C2: =IFERROR(COUNTIFS(日志重制!C:C,入场理由!A2,日志重制!Q:Q,"盈利")/COUNTIF(日志重制!C:C,入场理由!A2),0) -> 0 | D2: =COUNTIF(日志重制!C:C,A2) -> 0
A3: 交易区间内三推反转 | B3: =SUMIF(日志重制!C:C,A3,日志重制!R:R) -> 0 | C3: =IFERROR(COUNTIFS(日志重制!C:C,入场理由!A3,日志重制!Q:Q,"盈利")/COUNTIF(日志重制!C:C,入场理由!A3),0) -> 0 | D3: =COUNTIF(日志重制!C:C,A3) -> 0
A4: 交易区间内2ndleg陷阱 | B4: =SUMIF(日志重制!C:C,A4,日志重制!R:R) -> 0 | C4: =IFERROR(COUNTIFS(日志重制!C:C,入场理由!A4,日志重制!Q:Q,"盈利")/COUNTIF(日志重制!C:C,入场理由!A4),0) -> 0 | D4: =COUNTIF(日志重制!C:C,A4) -> 0
A5: 交易区间确认突破 | B5: =SUMIF(日志重制!C:C,A5,日志重制!R:R) -> 0 | C5: =IFERROR(COUNTIFS(日志重制!C:C,入场理由!A5,日志重制!Q:Q,"盈利")/COUNTIF(日志重制!C:C,入场理由!A5),0) -> 0 | D5: =COUNTIF(日志重制!C:C,A5) -> 0
A6: AIL，AIS首次回调 | B6: =SUMIF(日志重制!C:C,A6,日志重制!R:R) -> 0 | C6: =IFERROR(COUNTIFS(日志重制!C:C,入场理由!A6,日志重制!Q:Q,"盈利")/COUNTIF(日志重制!C:C,入场理由!A6),0) -> 0 | D6: =COUNTIF(日志重制!C:C,A6) -> 0
A7: 牛旗或熊旗 | B7: =SUMIF(日志重制!C:C,A7,日志重制!R:R) -> 0 | C7: =IFERROR(COUNTIFS(日志重制!C:C,入场理由!A7,日志重制!Q:Q,"盈利")/COUNTIF(日志重制!C:C,入场理由!A7),0) -> 0 | D7: =COUNTIF(日志重制!C:C,A7) -> 0
A8: 三推楔形、信号k | B8: =SUMIF(日志重制!C:C,A8,日志重制!R:R) -> 0 | C8: =IFERROR(COUNTIFS(日志重制!C:C,入场理由!A8,日志重制!Q:Q,"盈利")/COUNTIF(日志重制!C:C,入场理由!A8),0) -> 0 | D8: =COUNTIF(日志重制!C:C,A8) -> 0
A9: 三推楔形、双底 | B9: =SUMIF(日志重制!C:C,A9,日志重制!R:R) -> 0.13 | C9: =IFERROR(COUNTIFS(日志重制!C:C,入场理由!A9,日志重制!Q:Q,"盈利")/COUNTIF(日志重制!C:C,入场理由!A9),0) -> 1 | D9: =COUNTIF(日志重制!C:C,A9) -> 1
A10: 嵌套三推楔形 | B10: =SUMIF(日志重制!C:C,A10,日志重制!R:R) -> 0 | C10: =IFERROR(COUNTIFS(日志重制!C:C,入场理由!A10,日志重制!Q:Q,"盈利")/COUNTIF(日志重制!C:C,入场理由!A10),0) -> 0 | D10: =COUNTIF(日志重制!C:C,A10) -> 0
A11: 嵌套楔形、高潮、信号K | B11: =SUMIF(日志重制!C:C,A11,日志重制!R:R) -> 0 | C11: =IFERROR(COUNTIFS(日志重制!C:C,入场理由!A11,日志重制!Q:Q,"盈利")/COUNTIF(日志重制!C:C,入场理由!A11),0) -> 0 | D11: =COUNTIF(日志重制!C:C,A11) -> 0
A12: 三重底 | B12: =SUMIF(日志重制!C:C,A12,日志重制!R:R) -> 0 | C12: =IFERROR(COUNTIFS(日志重制!C:C,入场理由!A12,日志重制!Q:Q,"盈利")/COUNTIF(日志重制!C:C,入场理由!A12),0) -> 0 | D12: =COUNTIF(日志重制!C:C,A12) -> 0
A13: 三推楔形、双顶 | B13: =SUMIF(日志重制!C:C,A13,日志重制!R:R) -> 0 | C13: =IFERROR(COUNTIFS(日志重制!C:C,入场理由!A13,日志重制!Q:Q,"盈利")/COUNTIF(日志重制!C:C,入场理由!A13),0) -> 0 | D13: =COUNTIF(日志重制!C:C,A13) -> 0
... A25: 跳空开盘延续 | B25: =SUMIF(日志重制!C:C,A25,日志重制!R:R) -> 10.01 | C25: =IFERROR(COUNTIFS(日志重制!C:C,入场理由!A25,日志重制!Q:Q,"盈利")/COUNTIF(日志重制!C:C,入场理由!A25),0) -> 1 | D25: =COUNTIF(日志重制!C:C,A25) -> 1

Sheet 入场类型
A1: 入场类型 | B1: 盈亏金额 | C1: 胜率 | D1: 使用次数
A2: 趋势延续 | B2: =SUMIF(日志重制!D:D,入场类型!A2,日志重制!R:R) -> 10.42 | C2: =IFERROR(COUNTIFS(日志重制!D:D,A2,日志重制!Q:Q,"盈利")/COUNTIF(日志重制!D:D,A2),0) -> 1 | D2: =COUNTIF(日志重制!D:D,A2) -> 2
A3: 反转 | B3: =SUMIF(日志重制!D:D,入场类型!A3,日志重制!R:R) -> 0.13 | C3: =IFERROR(COUNTIFS(日志重制!D:D,A3,日志重制!Q:Q,"盈利")/COUNTIF(日志重制!D:D,A3),0) -> 1 | D3: =COUNTIF(日志重制!D:D,A3) -> 1
A4: 突破 | B4: =SUMIF(日志重制!D:D,入场类型!A4,日志重制!R:R) -> 0 | C4: =IFERROR(COUNTIFS(日志重制!D:D,A4,日志重制!Q:Q,"盈利")/COUNTIF(日志重制!D:D,A4),0) -> 0 | D4: =COUNTIF(日志重制!D:D,A4) -> 0
A5: 假突破 | B5: =SUMIF(日志重制!D:D,入场类型!A5,日志重制!R:R) -> 0 | C5: =IFERROR(COUNTIFS(日志重制!D:D,A5,日志重制!Q:Q,"盈利")/COUNTIF(日志重制!D:D,A5),0) -> 0 | D5: =COUNTIF(日志重制!D:D,A5) -> 0

Sheet 离场理由
A1: 离场理由 | B1: 使用次数
A2: 回测三推起点
A3: 止盈太远
A4: 推保本
A5: EMA20
A6: 移动止盈
A7: 止损触发（Stop out）
A8: 觉得有逆势压提前止盈
A9: 1倍MM
A10: 2倍MM
A11: 趋势线
A12: 回测通道起点

Sheet 错误原因
A1: 错误原因 | B1: 计数
A2: 逆势交易 | B2: =COUNTIF(日志重制!T2:T1048576,错误类型1!A2) -> 0
A3: 盈利单但是提前离场 | B3: =COUNTIF(日志重制!T2:T1048576,错误类型1!A3) -> 0
A4: 突破/反转判断错误 | B4: =COUNTIF(日志重制!T2:T1048576,错误类型1!A4) -> 0
A5: 错误的信号k线 | B5: =COUNTIF(日志重制!T2:T1048576,错误类型1!A5) -> 0
A6: 限价单入场 | B6: =COUNTIF(日志重制!T2:T1048576,错误类型1!A6) -> 0
A7: k线未收线就入场 | B7: =COUNTIF(日志重制!T2:T1048576,错误类型1!A7) -> 0
A8: 在阻力位买入，在支撑位卖出 | B8: =COUNTIF(日志重制!T2:T1048576,错误类型1!A8) -> 0
A9: 浮亏加仓 | B9: =COUNTIF(日志重制!T2:T1048576,错误类型1!A9) -> 0
A10: 市场背景理解错误 | B10: =COUNTIF(日志重制!T2:T1048576,错误类型1!A10) -> 0

Sheet 临时
B1: 做多 | C1: 横盘 | D1: 做空
A2: 上涨 | B2: 回调后的第二次进场信号 , 首次突破通道, 突破前高后产生了更高的高点, 第二次回踩缺口k线, 突破测试 | C2: 交易区间 | D2: W结构, W 结构突破后的首次回调
A3: 横盘 | B3: 突破 | C3: 假突破 | D3: 突破
A4: 下跌 | B4: W结构, W 结构突破后的首次回调 | C4: 交易区间 | D4: 回调后的第二次进场信号 , 首次突破通道, 突破前高后产生了更高的高点, 第二次回踩缺口k线, 突破测试
A6: 突破 | B6: 收敛三角旗形 | C6: 当前趋势强势延续 | D6: 回调
A7: 假突破 | B7: 突破后反转 | C7: 反转k | D7: 深度回调
A8: 趋势转换 | B8: 双底/双顶 | C8: 窄交易区间 | D8: 反转失败+第二次入场信号失效
B9: 首次回调 | D9: 首次反转
D10: 假突破
B11: 突破失败 | D11: 开盘区间
D12: 多周期共振

Sheet 别瞎搞日记本
A1: 日期 | B1: 是否执行规则？ | C1: 是否情绪稳定？ | D1: 是否做记录？ | E1: 是否提前准备？ | F1: 没有 FOMO？ | G1: 总盈亏 | H1: 备注
A2: 45762 | B2: ✅ | C2: ✅ | D2: ✅ | E2: ✅ | F2: ✅ | G2: -14
A3: 45763 | B3: ❌ | C3: ❌ | D3: ❌ | E3: ✅ | F3: ❌ | G3: -60

Sheet 日志
B1: 若判断错误，只需等待。除非可反向操作 | F1: =IFERROR(LOOKUP(2,1/(#REF!<>""),#REF!),"") | J1: =COUNTIFS(B:B,P1,N:N,"Lose") -> 0 | K1: =J1&"/3" -> 0/3 | L1: =COUNTIF(B:B,P1) -> 0 | M1: =L1&"/5" -> 0/5 | R1: 接受亏损，然后继续 | W1: 总共胜率 | X1: 总盈亏 | Y1: 平均盈利金额 | Z1: 平均亏损金额 | AA1: 盈亏比 | AC1: 交易区间内三推反转
A2: 日期 | B2: 备注 | C2: 入场理由 | D2: 类型 | E2: 离场理由/方式 | F2: 补充说明 | G2: 仓位大小 （填数字） | H2: 方向 | I2: 手续费 | J2: 入场净额 | K2: 离场净额1 | L2: 离场净额2 | M2: 盈亏情况 （会自动计算） | N2: 盈亏状态 （会自动计算） | O2: 累计盈亏 （会自动计算） | Q2: 错误原因 | R2: 隐 | S2: 限 | T2: 离 | U2: 止 | V2: 记 | W2: =COUNTIF($N$3:$N$404,"win")/(COUNTIF($N$3:$N$404,"win")+COUNTIF($N$3:$N$404,"lose")) -> 1 | X2: =SUM($M$3:$M$404) -> 40.04 | Y2: =AVERAGEIF(M:M,">0") -> 10.01 | Z2: =AVERAGEIF(M:M,"<0") -> #DIV/0! | AA2: =Y2/-Z2 -> #DIV/0! | AC2: 交易区间内2ndleg陷阱
A3: 46028.948 | B3: MES | C3: 跳空开盘延续 | D3: 趋势延续（Continuation） | E3: 觉得有逆势压提前止盈 | F3: 开盘大幅高开，预期强势上涨趋势延续，目标位跳空缺口向上1.705倍MM，K4-K6有交易转区间趋势，因此将目标位调整为前高之下提前离场，后续顺利到达原定目标位。 | G3: 1 | H3: Long | I3: =0.62*2 -> 1.24 | J3: 34728.75 | K3: 34740 | M3: =IF(ISBLANK(L3),IF(H3="Long",(K3-J3)*G3,(J3-K3)*G3)-I3,IF(H3="Long",(K3-J3)*(G3/2)+(L3-J3)*(G3/2)-I3,(J3-K3)*(G3/2)+(J3-L3)*(G3/2))-I3) -> 10.01 | N3: =_xlfn.IFS(M3>0,"win",M3<0,"lose",M3=0,"BE") -> win | O3: =$M$3 -> 10.01 | P3: #VALUE! | Q3: 盈利单但是提前离场(Letting a winning trade turn to losing) | R3: =IFERROR(LOOKUP(2,1/(B3:B1000<>""),B2:B1000),"") -> MES | AC3: 交易区间确认突破
A4: 46029.948 | B4: US500 | C4: 强趋势50%回调 | D4: 趋势延续（Continuation） | M4: =IF(ISBLANK(L4),IF(H4="Long",(K4-J4)*G4,(J4-K4)*G4),IF(H4="Long",(K4-J4)*(G4/2)+(L4-J4)*(G4/2),(J4-K4)*(G4/2)+(J4-L4)*(G4/2))) -> 0 | N4: =_xlfn.IFS(M4>0,"win",M4<0,"lose",M4=0,"BE") -> BE | O4: =M4+P7 -> 0 | S4: 入场原因 （可以自己定义） | T4: 盈亏金额 | U4: 胜率 | V4: 使用次数 | AC4: AIL，AIS首次回调
A5: 46028.948 | B5: MES | C5: 跳空开盘延续 | D5: 趋势延续（Continuation） | E5: 觉得有逆势压提前止盈 | F5: 开盘大幅高开，预期强势上涨趋势延续，目标位跳空缺口向上1.705倍MM，K4-K6有交易转区间趋势，因此将目标位调整为前高之下提前离场，后续顺利到达原定目标位。 | G5: 1 | H5: Long | I5: =0.62*2 -> 1.24 | J5: 34728.75 | K5: 34740 | M5: =IF(ISBLANK(L5),IF(H5="Long",(K5-J5)*G5,(J5-K5)*G5)-I5,IF(H5="Long",(K5-J5)*(G5/2)+(L5-J5)*(G5/2)-I5,(J5-K5)*(G5/2)+(J5-L5)*(G5/2))-I5) -> 10.01 | N5: =_xlfn.IFS(M5>0,"win",M5<0,"lose",M5=0,"BE") -> win | O5: =$M$3 -> 10.01 | S5: 交易区间内三推反转 | T5: =SUMIF(C:C,S5,M:M) -> 0 | U5: =IFERROR(COUNTIFS(C:C,S5,N:N,"win")/COUNTIF(C:C,S5),0) -> 0 | V5: =COUNTIF(C:C,S5) -> 0 | AC5: 牛旗或熊旗
A6: 46028.948 | B6: MES | C6: 跳空开盘延续 | D6: 趋势延续（Continuation） | E6: 觉得有逆势压提前止盈 | F6: 开盘大幅高开，预期强势上涨趋势延续，目标位跳空缺口向上1.705倍MM，K4-K6有交易转区间趋势，因此将目标位调整为前高之下提前离场，后续顺利到达原定目标位。 | G6: 1 | H6: Long | I6: =0.62*2 -> 1.24 | J6: 34728.75 | K6: 34740 | M6: =IF(ISBLANK(L6),IF(H6="Long",(K6-J6)*G6,(J6-K6)*G6)-I6,IF(H6="Long",(K6-J6)*(G6/2)+(L6-J6)*(G6/2)-I6,(J6-K6)*(G6/2)+(J6-L6)*(G6/2))-I6) -> 10.01 | N6: =_xlfn.IFS(M6>0,"win",M6<0,"lose",M6=0,"BE") -> win | O6: =$M$3 -> 10.01 | S6: 交易区间内2ndleg陷阱 | T6: =SUMIF(C:C,S6,M:M) -> 0 | U6: =IFERROR(COUNTIFS(C:C,S6,N:N,"win")/COUNTIF(C:C,S6),0) -> 0 | V6: =COUNTIF(C:C,S6) -> 0 | AC6: 三推楔形、信号k
A7: 46028.948 | B7: MES | C7: 跳空开盘延续 | D7: 趋势延续（Continuation） | E7: 觉得有逆势压提前止盈 | F7: 开盘大幅高开，预期强势上涨趋势延续，目标位跳空缺口向上1.705倍MM，K4-K6有交易转区间趋势，因此将目标位调整为前高之下提前离场，后续顺利到达原定目标位。 | G7: 1 | H7: Long | I7: =0.62*2 -> 1.24 | J7: 34728.75 | K7: 34740 | M7: =IF(ISBLANK(L7),IF(H7="Long",(K7-J7)*G7,(J7-K7)*G7)-I7,IF(H7="Long",(K7-J7)*(G7/2)+(L7-J7)*(G7/2)-I7,(J7-K7)*(G7/2)+(J7-L7)*(G7/2))-I7) -> 10.01 | N7: =_xlfn.IFS(M7>0,"win",M7<0,"lose",M7=0,"BE") -> win | O7: =$M$3 -> 10.01 | S7: 交易区间确认突破 | T7: =SUMIF(C:C,S7,M:M) -> 0 | U7: =IFERROR(COUNTIFS(C:C,S7,N:N,"win")/COUNTIF(C:C,S7),0) -> 0 | V7: =COUNTIF(C:C,S7) -> 0 | AC7: 三推楔形、双底
M8: =IF(ISBLANK(L8),IF(H8="Long",(K8-J8)*G8,(J8-K8)*G8),IF(H8="Long",(K8-J8)*(G8/2)+(L8-J8)*(G8/2),(J8-K8)*(G8/2)+(J8-L8)*(G8/2))) -> 0 | N8: =_xlfn.IFS(M8>0,"win",M8<0,"lose",M8=0,"BE") -> BE | O8: =M8+O7 -> 10.01 | S8: AIL，AIS首次回调 | T8: =SUMIF(C:C,S8,M:M) -> 0 | U8: =IFERROR(COUNTIFS(C:C,S8,N:N,"win")/COUNTIF(C:C,S8),0) -> 0 | V8: =COUNTIF(C:C,S8) -> 0 | AC8: 嵌套三推楔形
M9: =IF(ISBLANK(L9),IF(H9="Long",(K9-J9)*G9,(J9-K9)*G9),IF(H9="Long",(K9-J9)*(G9/2)+(L9-J9)*(G9/2),(J9-K9)*(G9/2)+(J9-L9)*(G9/2))) -> 0 | N9: =_xlfn.IFS(M9>0,"win",M9<0,"lose",M9=0,"BE") -> BE | O9: =M9+O8 -> 10.01 | S9: 牛旗或熊旗 | T9: =SUMIF(C:C,S9,M:M) -> 0 | U9: =IFERROR(COUNTIFS(C:C,S9,N:N,"win")/COUNTIF(C:C,S9),0) -> 0 | V9: =COUNTIF(C:C,S9) -> 0 | AC9: 嵌套楔形、高潮、信号K
M10: =IF(ISBLANK(L10),IF(H10="Long",(K10-J10)*G10,(J10-K10)*G10),IF(H10="Long",(K10-J10)*(G10/2)+(L10-J10)*(G10/2),(J10-K10)*(G10/2)+(J10-L10)*(G10/2))) -> 0 | N10: =_xlfn.IFS(M10>0,"win",M10<0,"lose",M10=0,"BE") -> BE | O10: =M10+O9 -> 10.01 | S10: 三推楔形、信号k | T10: =SUMIF(C:C,S10,M:M) -> 0 | U10: =IFERROR(COUNTIFS(C:C,S10,N:N,"win")/COUNTIF(C:C,S10),0) -> 0 | V10: =COUNTIF(C:C,S10) -> 0 | AC10: 三重底
M11: =IF(ISBLANK(L11),IF(H11="Long",(K11-J11)*G11,(J11-K11)*G11),IF(H11="Long",(K11-J11)*(G11/2)+(L11-J11)*(G11/2),(J11-K11)*(G11/2)+(J11-L11)*(G11/2))) -> 0 | N11: =_xlfn.IFS(M11>0,"win",M11<0,"lose",M11=0,"BE") -> BE | O11: =M11+O10 -> 10.01 | S11: 三推楔形、双底 | T11: =SUMIF(C:C,S11,M:M) -> 0 | U11: =IFERROR(COUNTIFS(C:C,S11,N:N,"win")/COUNTIF(C:C,S11),0) -> 0 | V11: =COUNTIF(C:C,S11) -> 0 | AC11: 三推楔形、双顶
M12: =IF(ISBLANK(L12),IF(H12="Long",(K12-J12)*G12,(J12-K12)*G12),IF(H12="Long",(K12-J12)*(G12/2)+(L12-J12)*(G12/2),(J12-K12)*(G12/2)+(J12-L12)*(G12/2))) -> 0 | N12: =_xlfn.IFS(M12>0,"win",M12<0,"lose",M12=0,"BE") -> BE | O12: =M12+O11 -> 10.01 | S12: 嵌套三推楔形 | T12: =SUMIF(C:C,S12,M:M) -> 0 | U12: =IFERROR(COUNTIFS(C:C,S12,N:N,"win")/COUNTIF(C:C,S12),0) -> 0 | V12: =COUNTIF(C:C,S12) -> 0 | AC12: 交易区间上下沿、信号K
M13: =IF(ISBLANK(L13),IF(H13="Long",(K13-J13)*G13,(J13-K13)*G13),IF(H13="Long",(K13-J13)*(G13/2)+(L13-J13)*(G13/2),(J13-K13)*(G13/2)+(J13-L13)*(G13/2))) -> 0 | N13: =_xlfn.IFS(M13>0,"win",M13<0,"lose",M13=0,"BE") -> BE | O13: =M13+O12 -> 10.01 | S13: 嵌套楔形、高潮、信号K | T13: =SUMIF(C:C,S13,M:M) -> 0 | U13: =IFERROR(COUNTIFS(C:C,S13,N:N,"win")/COUNTIF(C:C,S13),0) -> 0 | V13: =COUNTIF(C:C,S13) -> 0 | AC13: 交易区间内2ndleg、趋势线
M14: =IF(ISBLANK(L14),IF(H14="Long",(K14-J14)*G14,(J14-K14)*G14),IF(H14="Long",(K14-J14)*(G14/2)+(L14-J14)*(G14/2),(J14-K14)*(G14/2)+(J14-L14)*(G14/2))) -> 0 | N14: =_xlfn.IFS(M14>0,"win",M14<0,"lose",M14=0,"BE") -> BE | O14: =M14+O13 -> 10.01 | S14: 三重底 | T14: =SUMIF(C:C,S14,M:M) -> 0 | U14: =IFERROR(COUNTIFS(C:C,S14,N:N,"win")/COUNTIF(C:C,S14),0) -> 0 | V14: =COUNTIF(C:C,S14) -> 0 | AC14: EMA20、H/L1
M15: =IF(ISBLANK(L15),IF(H15="Long",(K15-J15)*G15,(J15-K15)*G15),IF(H15="Long",(K15-J15)*(G15/2)+(L15-J15)*(G15/2),(J15-K15)*(G15/2)+(J15-L15)*(G15/2))) -> 0 | N15: =_xlfn.IFS(M15>0,"win",M15<0,"lose",M15=0,"BE") -> BE | O15: =M15+O14 -> 10.01 | S15: 三推楔形、双顶 | T15: =SUMIF(C:C,S15,M:M) -> 0 | U15: =IFERROR(COUNTIFS(C:C,S15,N:N,"win")/COUNTIF(C:C,S15),0) -> 0 | V15: =COUNTIF(C:C,S15) -> 0 | AC15: 交易区间顶低限价单
M16: =IF(ISBLANK(L16),IF(H16="Long",(K16-J16)*G16,(J16-K16)*G16),IF(H16="Long",(K16-J16)*(G16/2)+(L16-J16)*(G16/2),(J16-K16)*(G16/2)+(J16-L16)*(G16/2))) -> 0 | N16: =_xlfn.IFS(M16>0,"win",M16<0,"lose",M16=0,"BE") -> BE | O16: =M16+O15 -> 10.01 | S16: 交易区间上下沿、信号K | T16: =SUMIF(C:C,S16,M:M) -> 0 | U16: =IFERROR(COUNTIFS(C:C,S16,N:N,"win")/COUNTIF(C:C,S16),0) -> 0 | V16: =COUNTIF(C:C,S16) -> 0 | AC16: 交易区间内2ndleg陷阱、信号K
M17: =IF(ISBLANK(L17),IF(H17="Long",(K17-J17)*G17,(J17-K17)*G17),IF(H17="Long",(K17-J17)*(G17/2)+(L17-J17)*(G17/2),(J17-K17)*(G17/2)+(J17-L17)*(G17/2))) -> 0 | N17: =_xlfn.IFS(M17>0,"win",M17<0,"lose",M17=0,"BE") -> BE | O17: =M17+O16 -> 10.01 | S17: 交易区间内2ndleg、趋势线 | T17: =SUMIF(C:C,S17,M:M) -> 0 | U17: =IFERROR(COUNTIFS(C:C,S17,N:N,"win")/COUNTIF(C:C,S17),0) -> 0 | V17: =COUNTIF(C:C,S17) -> 0 | AC17: 强趋势50%回调
M18: =IF(ISBLANK(L18),IF(H18="Long",(K18-J18)*G18,(J18-K18)*G18),IF(H18="Long",(K18-J18)*(G18/2)+(L18-J18)*(G18/2),(J18-K18)*(G18/2)+(J18-L18)*(G18/2))) -> 0 | N18: =_xlfn.IFS(M18>0,"win",M18<0,"lose",M18=0,"BE") -> BE | O18: =M18+O17 -> 10.01 | S18: EMA20、H/L1 | T18: =SUMIF(C:C,S18,M:M) -> 0 | U18: =IFERROR(COUNTIFS(C:C,S18,N:N,"win")/COUNTIF(C:C,S18),0) -> 0 | V18: =COUNTIF(C:C,S18) -> 0 | AC18: 三推楔形、EMA20、信号K
M19: =IF(ISBLANK(L19),IF(H19="Long",(K19-J19)*G19,(J19-K19)*G19),IF(H19="Long",(K19-J19)*(G19/2)+(L19-J19)*(G19/2),(J19-K19)*(G19/2)+(J19-L19)*(G19/2))) -> 0 | N19: =_xlfn.IFS(M19>0,"win",M19<0,"lose",M19=0,"BE") -> BE | O19: =M19+O18 -> 10.01 | S19: 交易区间顶低限价单 | T19: =SUMIF(C:C,S19,M:M) -> 0 | U19: =IFERROR(COUNTIFS(C:C,S19,N:N,"win")/COUNTIF(C:C,S19),0) -> 0 | V19: =COUNTIF(C:C,S19) -> 0 | AC19: 抛物线楔形、信号K
... M23: =IF(ISBLANK(L23),IF(H23="Long",(K23-J23)*G23,(J23-K23)*G23),IF(H23="Long",(K23-J23)*(G23/2)+(L23-J23)*(G23/2),(J23-K23)*(G23/2)+(J23-L23)*(G23/2))) -> 0 | N23: =_xlfn.IFS(M23>0,"win",M23<0,"lose",M23=0,"BE") -> BE | O23: =M23+O22 -> 10.01 | S23: 抛物线楔形、信号K | T23: =SUMIF(C:C,S23,M:M) -> 0 | U23: =IFERROR(COUNTIFS(C:C,S23,N:N,"win")/COUNTIF(C:C,S23),0) -> 0 | V23: =COUNTIF(C:C,S23) -> 0 | AC23: 跳空开盘延续
M24: =IF(ISBLANK(L24),IF(H24="Long",(K24-J24)*G24,(J24-K24)*G24),IF(H24="Long",(K24-J24)*(G24/2)+(L24-J24)*(G24/2),(J24-K24)*(G24/2)+(J24-L24)*(G24/2))) -> 0 | N24: =_xlfn.IFS(M24>0,"win",M24<0,"lose",M24=0,"BE") -> BE | O24: =M24+O23 -> 10.01 | S24: 趋势线、信号K | T24: =SUMIF(C:C,S24,M:M) -> 0 | U24: =IFERROR(COUNTIFS(C:C,S24,N:N,"win")/COUNTIF(C:C,S24),0) -> 0 | V24: =COUNTIF(C:C,S24) -> 0 | Y24: 做多 | Z24: 横盘 | AA24: 做空 | AC24: 不知道为什么开仓
M25: =IF(ISBLANK(L25),IF(H25="Long",(K25-J25)*G25,(J25-K25)*G25),IF(H25="Long",(K25-J25)*(G25/2)+(L25-J25)*(G25/2),(J25-K25)*(G25/2)+(J25-L25)*(G25/2))) -> 0 | N25: =_xlfn.IFS(M25>0,"win",M25<0,"lose",M25=0,"BE") -> BE | O25: =M25+O24 -> 10.01 | S25: H1、L1 | T25: =SUMIF(C:C,S25,M:M) -> 0 | U25: =IFERROR(COUNTIFS(C:C,S25,N:N,"win")/COUNTIF(C:C,S25),0) -> 0 | V25: =COUNTIF(C:C,S25) -> 0 | X25: 上涨 | Y25: 回调后的第二次进场信号 , 首次突破通道, 突破前高后产生了更高的高点, 第二次回踩缺口k线, 突破测试 | Z25: 交易区间 | AA25: W结构, W 结构突破后的首次回调
M26: =IF(ISBLANK(L26),IF(H26="Long",(K26-J26)*G26,(J26-K26)*G26),IF(H26="Long",(K26-J26)*(G26/2)+(L26-J26)*(G26/2),(J26-K26)*(G26/2)+(J26-L26)*(G26/2))) -> 0 | N26: =_xlfn.IFS(M26>0,"win",M26<0,"lose",M26=0,"BE") -> BE | O26: =M26+O25 -> 10.01 | S26: H2、L2 | T26: =SUMIF(C:C,S26,M:M) -> 0 | U26: =IFERROR(COUNTIFS(C:C,S26,N:N,"win")/COUNTIF(C:C,S26),0) -> 0 | V26: =COUNTIF(C:C,S26) -> 0 | X26: 横盘 | Y26: 突破 | Z26: 假突破 | AA26: 突破
M27: =IF(ISBLANK(L27),IF(H27="Long",(K27-J27)*G27,(J27-K27)*G27),IF(H27="Long",(K27-J27)*(G27/2)+(L27-J27)*(G27/2),(J27-K27)*(G27/2)+(J27-L27)*(G27/2))) -> 0 | N27: =_xlfn.IFS(M27>0,"win",M27<0,"lose",M27=0,"BE") -> BE | O27: =M27+O26 -> 10.01 | S27: 不知道为什么开仓 | T27: =SUMIF(C:C,S27,M:M) -> 0 | U27: =IFERROR(COUNTIFS(C:C,S27,N:N,"win")/COUNTIF(C:C,S27),0) -> 0 | V27: =COUNTIF(C:C,S27) -> 0 | X27: 下跌 | Y27: W结构, W 结构突破后的首次回调 | Z27: 交易区间 | AA27: 回调后的第二次进场信号 , 首次突破通道, 突破前高后产生了更高的高点, 第二次回踩缺口k线, 突破测试
M28: =IF(ISBLANK(L28),IF(H28="Long",(K28-J28)*G28,(J28-K28)*G28),IF(H28="Long",(K28-J28)*(G28/2)+(L28-J28)*(G28/2),(J28-K28)*(G28/2)+(J28-L28)*(G28/2))) -> 0 | N28: =_xlfn.IFS(M28>0,"win",M28<0,"lose",M28=0,"BE") -> BE | O28: =M28+O27 -> 10.01
M29: =IF(ISBLANK(L29),IF(H29="Long",(K29-J29)*G29,(J29-K29)*G29),IF(H29="Long",(K29-J29)*(G29/2)+(L29-J29)*(G29/2),(J29-K29)*(G29/2)+(J29-L29)*(G29/2))) -> 0 | N29: =_xlfn.IFS(M29>0,"win",M29<0,"lose",M29=0,"BE") -> BE | O29: =M29+O28 -> 10.01 | X29: 突破 | Y29: 收敛三角旗形 | Z29: 当前趋势强势延续 | AA29: 回调
M30: =IF(ISBLANK(L30),IF(H30="Long",(K30-J30)*G30,(J30-K30)*G30),IF(H30="Long",(K30-J30)*(G30/2)+(L30-J30)*(G30/2),(J30-K30)*(G30/2)+(J30-L30)*(G30/2))) -> 0 | N30: =_xlfn.IFS(M30>0,"win",M30<0,"lose",M30=0,"BE") -> BE | O30: =M30+O29 -> 10.01 | X30: 假突破 | Y30: 突破后反转 | Z30: 反转k | AA30: 深度回调
M31: =IF(ISBLANK(L31),IF(H31="Long",(K31-J31)*G31,(J31-K31)*G31),IF(H31="Long",(K31-J31)*(G31/2)+(L31-J31)*(G31/2),(J31-K31)*(G31/2)+(J31-L31)*(G31/2))) -> 0 | N31: =_xlfn.IFS(M31>0,"win",M31<0,"lose",M31=0,"BE") -> BE | O31: =M31+O30 -> 10.01 | X31: 趋势转换 | Y31: 双底/双顶 | Z31: 窄交易区间 | AA31: 反转失败+第二次入场信号失效
M32: =IF(ISBLANK(L32),IF(H32="Long",(K32-J32)*G32,(J32-K32)*G32),IF(H32="Long",(K32-J32)*(G32/2)+(L32-J32)*(G32/2),(J32-K32)*(G32/2)+(J32-L32)*(G32/2))) -> 0 | N32: =_xlfn.IFS(M32>0,"win",M32<0,"lose",M32=0,"BE") -> BE | O32: =M32+O31 -> 10.01 | Y32: 首次回调 | AA32: 首次反转
M33: =IF(ISBLANK(L33),IF(H33="Long",(K33-J33)*G33,(J33-K33)*G33),IF(H33="Long",(K33-J33)*(G33/2)+(L33-J33)*(G33/2),(J33-K33)*(G33/2)+(J33-L33)*(G33/2))) -> 0 | N33: =_xlfn.IFS(M33>0,"win",M33<0,"lose",M33=0,"BE") -> BE | O33: =M33+O32 -> 10.01 | AA33: 假突破
M34: =IF(ISBLANK(L34),IF(H34="Long",(K34-J34)*G34,(J34-K34)*G34),IF(H34="Long",(K34-J34)*(G34/2)+(L34-J34)*(G34/2),(J34-K34)*(G34/2)+(J34-L34)*(G34/2))) -> 0 | N34: =_xlfn.IFS(M34>0,"win",M34<0,"lose",M34=0,"BE") -> BE | O34: =M34+O33 -> 10.01 | S34: 类型 | T34: 盈利金额 | U34: 胜率 | V34: 使用次数 | Y34: 突破失败 | AA34: 开盘区间
M35: =IF(ISBLANK(L35),IF(H35="Long",(K35-J35)*G35,(J35-K35)*G35),IF(H35="Long",(K35-J35)*(G35/2)+(L35-J35)*(G35/2),(J35-K35)*(G35/2)+(J35-L35)*(G35/2))) -> 0 | N35: =_xlfn.IFS(M35>0,"win",M35<0,"lose",M35=0,"BE") -> BE | O35: =M35+O34 -> 10.01 | S35: 趋势延续（Continuation） | T35: =SUMIF(D:D,S35,M:M) -> 40.04 | U35: =IFERROR(COUNTIFS(D:D,S35,N:N,"win")/COUNTIF(D:D,S35),0) -> 0.8 | V35: =COUNTIF(D:D,S35) -> 5 | AA35: 多周期共振
M36: =IF(ISBLANK(L36),IF(H36="Long",(K36-J36)*G36,(J36-K36)*G36),IF(H36="Long",(K36-J36)*(G36/2)+(L36-J36)*(G36/2),(J36-K36)*(G36/2)+(J36-L36)*(G36/2))) -> 0 | N36: =_xlfn.IFS(M36>0,"win",M36<0,"lose",M36=0,"BE") -> BE | O36: =M36+O35 -> 10.01 | S36: 反转（Reversal） | T36: =SUMIF(D:D,S36,M:M) -> 0 | U36: =IFERROR(COUNTIFS(D:D,S36,N:N,"win")/COUNTIF(D:D,S36),0) -> 0 | V36: =COUNTIF(D:D,S36) -> 0
M37: =IF(ISBLANK(L37),IF(H37="Long",(K37-J37)*G37,(J37-K37)*G37),IF(H37="Long",(K37-J37)*(G37/2)+(L37-J37)*(G37/2),(J37-K37)*(G37/2)+(J37-L37)*(G37/2))) -> 0 | N37: =_xlfn.IFS(M37>0,"win",M37<0,"lose",M37=0,"BE") -> BE | O37: =M37+O36 -> 10.01 | S37: 突破（BO） | T37: =SUMIF(D:D,S37,M:M) -> 0 | U37: =IFERROR(COUNTIFS(D:D,S37,N:N,"win")/COUNTIF(D:D,S37),0) -> 0 | V37: =COUNTIF(D:D,S37) -> 0
M38: =IF(ISBLANK(L38),IF(H38="Long",(K38-J38)*G38,(J38-K38)*G38),IF(H38="Long",(K38-J38)*(G38/2)+(L38-J38)*(G38/2),(J38-K38)*(G38/2)+(J38-L38)*(G38/2))) -> 0 | N38: =_xlfn.IFS(M38>0,"win",M38<0,"lose",M38=0,"BE") -> BE | O38: =M38+O37 -> 10.01 | Q38: 错误的信号k线（Wrong Signal bar） | S38: 假突破（fBO） | T38: =SUMIF(D:D,S38,M:M) -> 0 | U38: =IFERROR(COUNTIFS(D:D,S38,N:N,"win")/COUNTIF(D:D,S38),0) -> 0 | V38: =COUNTIF(D:D,S38) -> 0
M39: =IF(ISBLANK(L39),IF(H39="Long",(K39-J39)*G39,(J39-K39)*G39),IF(H39="Long",(K39-J39)*(G39/2)+(L39-J39)*(G39/2),(J39-K39)*(G39/2)+(J39-L39)*(G39/2))) -> 0 | N39: =_xlfn.IFS(M39>0,"win",M39<0,"lose",M39=0,"BE") -> BE | O39: =M39+O38 -> 10.01
M40: =IF(ISBLANK(L40),IF(H40="Long",(K40-J40)*G40,(J40-K40)*G40),IF(H40="Long",(K40-J40)*(G40/2)+(L40-J40)*(G40/2),(J40-K40)*(G40/2)+(J40-L40)*(G40/2))) -> 0 | N40: =_xlfn.IFS(M40>0,"win",M40<0,"lose",M40=0,"BE") -> BE | O40: =M40+O39 -> 10.01
M41: =IF(ISBLANK(L41),IF(H41="Long",(K41-J41)*G41,(J41-K41)*G41),IF(H41="Long",(K41-J41)*(G41/2)+(L41-J41)*(G41/2),(J41-K41)*(G41/2)+(J41-L41)*(G41/2))) -> 0 | N41: =_xlfn.IFS(M41>0,"win",M41<0,"lose",M41=0,"BE") -> BE | O41: =M41+O40 -> 10.01
M42: =IF(ISBLANK(L42),IF(H42="Long",(K42-J42)*G42,(J42-K42)*G42),IF(H42="Long",(K42-J42)*(G42/2)+(L42-J42)*(G42/2),(J42-K42)*(G42/2)+(J42-L42)*(G42/2))) -> 0 | N42: =_xlfn.IFS(M42>0,"win",M42<0,"lose",M42=0,"BE") -> BE | O42: =M42+O41 -> 10.01
M43: =IF(ISBLANK(L43),IF(H43="Long",(K43-J43)*G43,(J43-K43)*G43),IF(H43="Long",(K43-J43)*(G43/2)+(L43-J43)*(G43/2),(J43-K43)*(G43/2)+(J43-L43)*(G43/2))) -> 0 | N43: =_xlfn.IFS(M43>0,"win",M43<0,"lose",M43=0,"BE") -> BE | O43: =M43+O42 -> 10.01
...

Sheet 错误类型1
A1: 错误原因 | B1: 计数 | D1: 离场理由
A2: 逆势交易（Fading a strong trend） | B2: =COUNTIF(日志!$Q3:$Q1048576,错误类型1!A2) -> 0 | D2: 回测三推起点
A3: 盈利单但是提前离场(Letting a winning trade turn to losing) | B3: =COUNTIF(日志!$Q3:$Q1048576,错误类型1!A3) -> 1 | D3: 止盈太远
A4: 突破/反转判断错误（BW/OL） | B4: =COUNTIF(日志!$Q3:$Q1048576,错误类型1!A4) -> 1 | D4: 推保本
A5: 错误的信号k线（Wrong Signal bar） | B5: =COUNTIF(日志!$Q3:$Q1048576,错误类型1!A5) -> 3 | D5: EMA20
A6: 限价单入场（limit entry） | B6: =COUNTIF(日志!$Q3:$Q1048576,错误类型1!A6) -> 0 | D6: 移动止盈
A7: k线未收线就入场（Entry mid-bar） | B7: =COUNTIF(日志!$Q3:$Q1048576,错误类型1!A7) -> 0 | D7: 止损触发（Stop out）
A8: 在阻力位买入，在支撑位卖出（buy into resist, sell into support） | B8: =COUNTIF(日志!$Q3:$Q1048576,错误类型1!A8) -> 0 | D8: 觉得有逆势压提前止盈
A9: 浮亏加仓（scaling into a losing position）. | B9: =COUNTIF(日志!$Q3:$Q1048576,错误类型1!A9) -> 0 | D9: 1倍MM
A10: 市场背景理解错误（bad structure reading） | B10: =COUNTIF(日志!$Q3:$Q1048576,错误类型1!A10) -> 0 | D10: 2倍MM
D11: 趋势线
D12: 回测通道起点
